<robot name="onshape">
<link name="body">
<visual>
<origin xyz="-9.18996e-18 -1.11022e-16 -0.04" rpy="-3.14159 -1.41718e-16 3.14159" />
<geometry>
<mesh filename="package://body.stl"/>
</geometry>
<material name="body_material">
<color rgba="0.615686 0.811765 0.929412 1.0"/>
</material>
</visual>
<collision>
<origin xyz="-9.18996e-18 -1.11022e-16 -0.04" rpy="-3.14159 -1.41718e-16 3.14159" />
<geometry>
<mesh filename="package://body.stl"/>
</geometry>
<material name="body_material">
<color rgba="0.615686 0.811765 0.929412 1.0"/>
</material>
</collision>
<inertial>
<origin xyz="-9.18996e-18 -1.16513e-16 -0.04" rpy="0 0 0"/>
<mass value="7.22018" />
<inertia ixx="0.133175" ixy="5.3548e-18"  ixz="-7.147e-18" iyy="0.0578714" iyz="2.75575e-17" izz="0.183606" />
</inertial>
</link>

<link name="leg">
<visual>
<origin xyz="0.2 0 0.15" rpy="1.5708 1.5708 0" />
<geometry>
<mesh filename="package://leg.stl"/>
</geometry>
<material name="leg_material">
<color rgba="0.647059 0.647059 0.647059 1.0"/>
</material>
</visual>
<collision>
<origin xyz="0.2 0 0.15" rpy="1.5708 1.5708 0" />
<geometry>
<mesh filename="package://leg.stl"/>
</geometry>
<material name="leg_material">
<color rgba="0.647059 0.647059 0.647059 1.0"/>
</material>
</collision>
<inertial>
<origin xyz="0.150043 0.019542 0.15" rpy="0 0 0"/>
<mass value="1.46202" />
<inertia ixx="0.0603673" ixy="6.94831e-37"  ixz="0.00199071" iyy="0.0253453" iyz="1.61377e-38" izz="0.036191" />
</inertial>
</link>

<link name="wheel">
<visual>
<origin xyz="-0.146667 1.11022e-16 0.175" rpy="1.5708 1.5708 0" />
<geometry>
<mesh filename="package://wheel.stl"/>
</geometry>
<material name="wheel_material">
<color rgba="0.917647 0.917647 0.917647 1.0"/>
</material>
</visual>
<collision>
<origin xyz="-0.146667 1.11022e-16 0.175" rpy="1.5708 1.5708 0" />
<geometry>
<mesh filename="package://wheel.stl"/>
</geometry>
<material name="wheel_material">
<color rgba="0.917647 0.917647 0.917647 1.0"/>
</material>
</collision>
<inertial>
<origin xyz="-8.32667e-17 -4.0857e-18 -0.025" rpy="0 0 0"/>
<mass value="1.81751" />
<inertia ixx="0.00347125" ixy="-7.44518e-38"  ixz="-3.3427e-37" iyy="0.00618521" iyz="0" izz="0.00347125" />
</inertial>
</link>

<joint name="front_right_wheel" type="revolute">
<origin xyz="0.346667 -1.66533e-16 -0.025" rpy="1.41928e-16 1.30419e-17 -0.0872665" />
<parent link="leg" />
<child link="wheel" />
<axis xyz="0 0 1"/>
<limit effort="1" velocity="20" />
<joint_properties friction="0.0"/>
</joint>

<link name="wheel_2">
<visual>
<origin xyz="-0.146667 1.11022e-16 0.175" rpy="1.5708 1.5708 0" />
<geometry>
<mesh filename="package://wheel.stl"/>
</geometry>
<material name="wheel_material">
<color rgba="0.917647 0.917647 0.917647 1.0"/>
</material>
</visual>
<collision>
<origin xyz="-0.146667 1.11022e-16 0.175" rpy="1.5708 1.5708 0" />
<geometry>
<mesh filename="package://wheel.stl"/>
</geometry>
<material name="wheel_material">
<color rgba="0.917647 0.917647 0.917647 1.0"/>
</material>
</collision>
<inertial>
<origin xyz="8.32667e-17 -4.0857e-18 -0.025" rpy="0 0 0"/>
<mass value="1.81751" />
<inertia ixx="0.00347125" ixy="4.57432e-34"  ixz="-5.07851e-50" iyy="0.00618521" iyz="-6.86696e-19" izz="0.00347125" />
</inertial>
</link>

<joint name="front_left_wheel" type="revolute">
<origin xyz="0.346667 -1.80411e-16 0.325" rpy="-3.14159 -1.77836e-16 -2.35619" />
<parent link="leg" />
<child link="wheel_2" />
<axis xyz="0 0 1"/>
<limit effort="1" velocity="20" />
<joint_properties friction="0.0"/>
</joint>

<joint name="front_leg" type="revolute">
<origin xyz="-0.15 -0.2 -0.04" rpy="-1.5708 -1.66533e-16 -1.5708" />
<parent link="body" />
<child link="leg" />
<axis xyz="0 0 1"/>
<limit effort="1" velocity="20" lower="-3.14159" upper="3.14159"/>
<joint_properties friction="0.0"/>
</joint>

<link name="leg_2">
<visual>
<origin xyz="0.2 6.93889e-18 0.15" rpy="1.5708 1.5708 0" />
<geometry>
<mesh filename="package://leg.stl"/>
</geometry>
<material name="leg_material">
<color rgba="0.647059 0.647059 0.647059 1.0"/>
</material>
</visual>
<collision>
<origin xyz="0.2 6.93889e-18 0.15" rpy="1.5708 1.5708 0" />
<geometry>
<mesh filename="package://leg.stl"/>
</geometry>
<material name="leg_material">
<color rgba="0.647059 0.647059 0.647059 1.0"/>
</material>
</collision>
<inertial>
<origin xyz="0.150043 0.019542 0.15" rpy="0 0 0"/>
<mass value="1.46202" />
<inertia ixx="0.0603673" ixy="-6.39636e-34"  ixz="0.00199071" iyy="0.0253453" iyz="4.25487e-33" izz="0.036191" />
</inertial>
</link>

<link name="wheel_3">
<visual>
<origin xyz="-0.146667 1.11022e-16 0.175" rpy="1.5708 1.5708 0" />
<geometry>
<mesh filename="package://wheel.stl"/>
</geometry>
<material name="wheel_material">
<color rgba="0.917647 0.917647 0.917647 1.0"/>
</material>
</visual>
<collision>
<origin xyz="-0.146667 1.11022e-16 0.175" rpy="1.5708 1.5708 0" />
<geometry>
<mesh filename="package://wheel.stl"/>
</geometry>
<material name="wheel_material">
<color rgba="0.917647 0.917647 0.917647 1.0"/>
</material>
</collision>
<inertial>
<origin xyz="-8.32667e-17 -4.0857e-18 -0.025" rpy="0 0 0"/>
<mass value="1.81751" />
<inertia ixx="0.00347125" ixy="5.55291e-33"  ixz="-1.36917e-33" iyy="0.00618521" iyz="0" izz="0.00347125" />
</inertial>
</link>

<joint name="back_right_wheel" type="revolute">
<origin xyz="0.346667 -1.04083e-16 -0.025" rpy="3.15882e-15 1.24219e-14 -3.1003" />
<parent link="leg_2" />
<child link="wheel_3" />
<axis xyz="0 0 1"/>
<limit effort="1" velocity="20" />
<joint_properties friction="0.0"/>
</joint>

<link name="wheel_4">
<visual>
<origin xyz="-0.146667 1.11022e-16 0.175" rpy="1.5708 1.5708 0" />
<geometry>
<mesh filename="package://wheel.stl"/>
</geometry>
<material name="wheel_material">
<color rgba="0.917647 0.917647 0.917647 1.0"/>
</material>
</visual>
<collision>
<origin xyz="-0.146667 1.11022e-16 0.175" rpy="1.5708 1.5708 0" />
<geometry>
<mesh filename="package://wheel.stl"/>
</geometry>
<material name="wheel_material">
<color rgba="0.917647 0.917647 0.917647 1.0"/>
</material>
</collision>
<inertial>
<origin xyz="-8.32667e-17 -4.0857e-18 -0.025" rpy="0 0 0"/>
<mass value="1.81751" />
<inertia ixx="0.00347125" ixy="7.01779e-34"  ixz="0" iyy="0.00618521" iyz="0" izz="0.00347125" />
</inertial>
</link>

<joint name="back_left_wheel" type="revolute">
<origin xyz="0.346667 -1.04083e-16 0.325" rpy="-3.14159 2.47943e-14 3.14159" />
<parent link="leg_2" />
<child link="wheel_4" />
<axis xyz="0 0 1"/>
<limit effort="1" velocity="20" />
<joint_properties friction="0.0"/>
</joint>

<joint name="back_leg" type="revolute">
<origin xyz="-0.15 0.2 -0.04" rpy="1.5708 -3.33067e-16 1.5708" />
<parent link="body" />
<child link="leg_2" />
<axis xyz="0 0 1"/>
<limit effort="1" velocity="20" lower="-3.14159" upper="3.14159"/>
<joint_properties friction="0.0"/>
</joint>


</robot>
